Workbook
Name _ftn1: 'Summary (2.8 PEA)'!#REF!
Name _ftn2: 'Summary (2.8 PEA)'!#REF!
Name _ftn3: 'Summary (2.8 PEA)'!#REF!
Name _ftn4: 'Summary (2.8 PEA)'!$A$90
Name _ftn5: 'Summary (2.8 PEA)'!$A$92
Name _ftn6: 'Summary (2.8 PEA)'!$A$93
Name _ftn7: 'Summary (2.8 PEA)'!$A$63
Name _ftnref1: 'Summary (2.8 PEA)'!#REF!
Name _ftnref2: 'Summary (2.8 PEA)'!#REF!
Name _ftnref3: 'Summary (2.8 PEA)'!#REF!
Name _ftnref4: 'Summary (2.8 PEA)'!$K$78
Name _ftnref5: 'Summary (2.8 PEA)'!#REF!
Name _ftnref6: 'Summary (2.8 PEA)'!$L$78
Name _ftnref7: 'Summary (2.8 PEA)'!#REF!
Name BaitSuppBC: '[1]BCA BAIT SUPP'!$C$28
Name BaitSuppBEP: '[1]BCA BAIT SUPP'!#REF!
Name BaitSuppIRR: '[1]BCA BAIT SUPP'!#REF!
Name BaitSuppNPV: '[1]BCA BAIT SUPP'!$C$27
Name BaitSuppPBP: '[1]BCA BAIT SUPP'!#REF!
Name BaitSuppROE: '[1]BCA BAIT SUPP'!#REF!
Name BufferArea: '[1]Land use'!$BK$14
Name CostCurrent: #REF!
Name CostHoneyLoss: #REF!
Name CostHumanHealth: #REF!
Name CostSecondaryOutbreaks: #REF!
Name CountryName: '[1]Land use'!$BK$11
Name CurrentBC: '[1]BCA COVER SPRAY'!$C$28
Name CurrentControlMethod: '[1]Current control strategy'!$C$5
Name CurrentNPV: '[1]BCA COVER SPRAY'!$C$27
Name CurrentPerCentLoss: '[1]Production - Inputs'!$N$21
Name CurrentTonnesOfPostHarvestTreatment: #REF!
Name CurrentYield: '[1]Background data'!#REF!
Name DiscountRate: '[1]Background data'!$C$6
Name ExchangeRate: '[1]Background data'!$C$9
Name FactoryCost: '[1]Flies and Factory'!$C$13
Name FactoryYesNo: '[1]Flies and Factory'!$C$8
Name FlyNonFliersBought: '[1]Flies and Factory'!$C$18
Name FlyNonFliersOwnFactory: '[1]Flies and Factory'!$C$11
Name LossCurrent: '[1]Prod and Marketing - Output'!$T$3
Name MarketLoss: '[1]Prod and Marketing - Output'!$AC$3
Name No: '[1]Flies and Factory'!$R$4
Name OrchardArea: '[1]Land use'!$BK$13
Name OtherHostArea: '[1]Land use'!$BK$16
Name PotentialProduction000T: #REF!
Name ProjectDuration: '[1]Background data'!$C$5
Name ResidualLossBait: '[1]Background data'!$C$12
Name ResidualLossSIT: '[1]Background data'!$C$13
Name SITSuppBC: '[1]BCA SIT SUPP'!$C$29
Name SITSUPPNPV: '[1]BCA SIT SUPP'!$C$28
Name SprayPrice: '[1]Background data'!#REF!
Name TotalArea: '[1]Land use'!$BK$18
Name TotalCostConvControl: #REF!
Name TotalOrchardRatio: '[1]Land use'!$BK$19
Name TrapServiceCost: #REF!
Name UrbanArea: '[1]Land use'!$BK$15
Name Yes: '[1]Flies and Factory'!$R$3
Name Yield: '[1]Background data'!#REF!
Name ZoneName: '[1]Land use'!$BK$12

Sheet Main - PEA
B1: Pesticide Environmental Accounting - User Interface Page

Sheet Integration Inputs
B1: Input and integration page of Pretty et al. data with Kovach et al. EIQ system
B5: Pretty et al. 2001 UK, USA and Germany (adjusted to 1996 prices)
C6: UK | E6: USA | G6: Germany | Q6: UK | S6: USA | U6: Germany
B7: Active Ingredient (a.i.) consumption kg (late 1990s) | C7: 22500000 | E7: 425000000 | G7: 26500000 | Q7: 22500000 | S7: 425000000 | U7: 26500000
C9: UK | E9: USA | G9: Germany | Q9: UK | S9: USA | U9: Germany
B10: 1996 GBP | C10: Cost | D10: Cost per Kg ai | E10: Cost | F10: Cost per Kg ai | G10: Cost | H10: Cost per Kg ai | Q10: Cost | R10: Cost per Kg ai | S10: Cost | T10: Cost per Kg ai | U10: Cost | V10: Cost per Kg ai
B11: Pesticides in sources of drinking water | C11: 120000000 | D11: =C11/C$7 -> 5.3333333 | E11: 592000000 | F11: =E11/E$7 -> 1.3929412 | G11: 58000000 | H11: =G11/G$7 -> 2.1886792 | Q11: 120000000 | R11: =Q11/Q$7 -> 5.3333333 | S11: 592000000 | T11: =S11/S$7 -> 1.3929412 | U11: 58000000 | V11: =U11/U$7 -> 2.1886792
B12: Pollution incidents, fish deaths and monitoring costs | C12: =0.5*17000000 -> 8500000 | D12: =C12/C$7 -> 0.37777778 | E12: =0.5*170000000 -> 85000000 | F12: =E12/E$7 -> 0.2 | G12: =0.5*33000000 -> 16500000 | H12: =G12/G$7 -> 0.62264151 | Q12: =0.5*17000000 -> 8500000 | R12: =Q12/Q$7 -> 0.37777778 | S12: =0.5*170000000 -> 85000000 | T12: =S12/S$7 -> 0.2 | U12: =0.5*33000000 -> 16500000 | V12: =U12/U$7 -> 0.62264151
B13: Biodiversity/wildlife losses | C13: =0.5*25000000 -> 12500000 | D13: =C13/C$7 -> 0.55555556 | E13: =0.5*218000000 -> 109000000 | F13: =E13/E$7 -> 0.25647059 | G13: =0.5*4000000 -> 2000000 | H13: =G13/G$7 -> 0.075471698 | Q13: =0.5*25000000 -> 12500000 | R13: =Q13/Q$7 -> 0.55555556 | S13: =0.5*218000000 -> 109000000 | T13: =S13/S$7 -> 0.25647059 | U13: =0.5*4000000 -> 2000000 | V13: =U13/U$7 -> 0.075471698
B14: Cultural, landscape, toursim etc. (Hedgerow and dry stone walls) | C14: =0.5*99000000 -> 49500000 | D14: =C14/C$7 -> 2.2 | F14: =E14/E$7 -> 0 | H14: =G14/G$7 -> 0 | Q14: =0.5*99000000 -> 49500000 | R14: =Q14/Q$7 -> 2.2 | T14: =S14/S$7 -> 0 | V14: =U14/U$7 -> 0
B15: Bee colony losses | C15: =0.5*2000000 -> 1000000 | D15: =C15/C$7 -> 0.044444444 | E15: =0.5*152000000 -> 76000000 | F15: =E15/E$7 -> 0.17882353 | G15: =0.5*1000000 -> 500000 | H15: =G15/G$7 -> 0.018867925 | Q15: =0.5*2000000 -> 1000000 | R15: =Q15/Q$7 -> 0.044444444 | S15: =0.5*152000000 -> 76000000 | T15: =S15/S$7 -> 0.17882353 | U15: =0.5*1000000 -> 500000 | V15: =U15/U$7 -> 0.018867925
B16: Acute effects of pesticides to human health | C16: 1000000 | D16: =C16/C$7 -> 0.044444444 | E16: 88000000 | F16: =E16/E$7 -> 0.20705882 | G16: 9000000 | H16: =G16/G$7 -> 0.33962264 | Q16: 1000000 | R16: =Q16/Q$7 -> 0.044444444 | S16: 88000000 | T16: =S16/S$7 -> 0.20705882 | U16: 9000000 | V16: =U16/U$7 -> 0.33962264
B17: Total | C17: =SUM(C11:C16) -> 192500000 | D17: =C17/C$7 -> 8.5555556 | E17: =SUM(E11:E16) -> 950000000 | F17: =E17/E$7 -> 2.2352941 | G17: =SUM(G11:G16) -> 86000000 | H17: =G17/G$7 -> 3.245283
B27: Inflation and Euro conversion of £ data | Q27: ='UK Deflator'!B6 -> 1996-97
C29: UK | E29: USA | G29: Germany | Q29: ='UK Deflator'!B7 -> 1997-98
B30: =_xlfn.CONCAT("20",RIGHT(H39,2))&" Euros" -> 2024 Euros | C30: Cost | D30: Cost per Kg ai | E30: Cost | F30: Cost per Kg ai | G30: Cost | H30: Cost per Kg ai | Q30: ='UK Deflator'!B8 -> 1998-99
B31: Pesticides in sources of drinking water | C31: ='UK Deflator'!E36 -> 2.584344e+08 | D31: =C31/C$7 -> 11.485973 | E31: ='US Deflator'!E36 -> 1.5335229e+09 | F31: =E31/E$7 -> 3.6082891 | G31: ='German Deflator'!E36 -> 2.1967524e+08 | H31: =G31/G$7 -> 8.2896315 | Q31: ='UK Deflator'!B9 -> 1999-00
B32: Pollution incidents, fish deaths and monitoring costs | C32: ='UK Deflator'!F36 -> 18305770 | D32: =C32/C$7 -> 0.81358979 | E32: ='US Deflator'!F36 -> 2.2018487e+08 | F32: =E32/E$7 -> 0.51808205 | G32: ='German Deflator'!F36 -> 62493817 | H32: =G32/G$7 -> 2.3582572 | Q32: ='UK Deflator'!B10 -> 2000-01
B33: Biodiversity/wildlife losses | C33: ='UK Deflator'!G36 -> 26920250 | D33: =C33/C$7 -> 1.1964556 | E33: ='US Deflator'!G36 -> 2.8235471e+08 | F33: =E33/E$7 -> 0.66436403 | G33: ='German Deflator'!G36 -> 7575008.1 | H33: =G33/G$7 -> 0.28584936 | Q33: ='UK Deflator'!B11 -> 2001-02
B34: Cultural, landscape, toursim etc. (Hedgerow and dry stone walls) | C34: ='UK Deflator'!H36 -> 1.0660419e+08 | D34: =C34/C$7 -> 4.7379641 | E34: ='US Deflator'!H36 -> 0 | F34: =E34/E$7 -> 0 | G34: ='German Deflator'!H36 -> 0 | H34: =G34/G$7 -> 0 | Q34: ='UK Deflator'!B12 -> 2002-03
B35: Bee colony losses | C35: ='UK Deflator'!I36 -> 2153620 | D35: =C35/C$7 -> 0.095716446 | E35: ='US Deflator'!I36 -> 1.9687118e+08 | F35: =E35/E$7 -> 0.4632263 | G35: ='German Deflator'!I36 -> 1893752 | H35: =G35/G$7 -> 0.071462341 | Q35: ='UK Deflator'!B13 -> 2003-04
B36: Acute effects of pesticides to human health | C36: ='UK Deflator'!I36 -> 2153620 | D36: =C36/C$7 -> 0.095716446 | E36: ='US Deflator'!J36 -> 2.279561e+08 | F36: =E36/E$7 -> 0.53636729 | G36: ='German Deflator'!J36 -> 34087537 | H36: =G36/G$7 -> 1.2863221 | Q36: ='UK Deflator'!B14 -> 2004-05
B37: Total | C37: =SUM(C31:C36) -> 4.1457185e+08 | D37: =C37/C$7 -> 18.425416 | E37: =SUM(E31:E36) -> 2.4608897e+09 | F37: =E37/E$7 -> 5.7903287 | G37: =SUM(G31:G36) -> 3.2572535e+08 | H37: =G37/G$7 -> 12.291523 | Q37: ='UK Deflator'!B15 -> 2005-06
Q38: ='UK Deflator'!B16 -> 2006-07
G39: Inflate to Year: | H39: 2023-24 | Q39: ='UK Deflator'!B17 -> 2007-08
C40: Mean Cost per Kg ai | Q40: ='UK Deflator'!B18 -> 2008-09
B41: Pesticides in sources of drinking water | C41: =AVERAGE(D31,F31,H31) -> 7.7946314 | Q41: ='UK Deflator'!B19 -> 2009-10
B42: Pollution incidents, fish deaths and monitoring costs | C42: =AVERAGE(D32,F32,H32) -> 1.2299764 | Q42: ='UK Deflator'!B27 -> 2017-18
B43: Biodiversity/wildlife losses | C43: =AVERAGE(D33,F33,H33) -> 0.71555632 | Q43: ='UK Deflator'!B28 -> 2018-19
B44: Cultural, landscape, toursim etc. (Hedgerows, dry stone walls, perception of spraying) | C44: =AVERAGE(D34,F34,H34) -> 1.5793214 | Q44: ='UK Deflator'!B29 -> 2019-20
B45: Bee colony losses | C45: =AVERAGE(D35,F35,H35) -> 0.21013503 | Q45: ='UK Deflator'!B30 -> 2020-21
B46: Acute effects of pesticides to human health | C46: =AVERAGE(D36,F36,H36) -> 0.63946862 | Q46: ='UK Deflator'!B31 -> 2021-22
B47: Total | C47: =AVERAGE(D37,F37,H37) -> 12.169089 | Q47: ='UK Deflator'!B32 -> 2022-23
Q48: ='UK Deflator'!B33 -> 2023-24
B50: Distribution of Pretty et al. costs over Kovachs et al EIQ system | C50: Pesticides in sources of drinking water | D50: Pollution incidents, fish deaths and monitoring costs | E50: Biodiversity / wildlife losses | F50: Landscape / Cultural / tourism value | G50: Bee colony losses | H50: Acute effects of pesticides to human health
A51: human | B51: human | C51: 1 | H51: 1 | V51: 0.8
A52: env | B52: env | D52: 0.5 | F52: 1 | V52: 0.15
A53: ecoterr | B53: ecoterr | E53: 0.5 | G53: 1 | Q53: 1 | T53: 0.5 | V53: 0.05
A54: ecoaqu | B54: ecoaqu | D54: 0.5 | E54: 0.5 | R54: 0.5
R55: 0.5 | S55: 0.3
...

Sheet UK Deflator
B2: Source: | C2: https://www.gov.uk/government/uploads/system/uploads/attachment_data/file/624527/GDP_Deflators_Qtrly_National_Accounts_June_2017_update.csv/preview
B4: GDP deflator at market prices
B5: Financial Year | D5: % change on previous year | E5: ='Integration Inputs'!B11 -> Pesticides in sources of drinking water | F5: ='Integration Inputs'!B12 -> Pollution incidents, fish deaths and monitoring costs | G5: ='Integration Inputs'!B13 -> Biodiversity/wildlife losses | H5: ='Integration Inputs'!B14 -> Cultural, landscape, toursim etc. (Hedgerow and dry stone walls) | I5: ='Integration Inputs'!B15 -> Bee colony losses | J5: ='Integration Inputs'!B16 -> Acute effects of pesticides to human health
B6: 1996-97 | C6: 52.6908 | D6: 3.3929402 | E6: ='Integration Inputs'!C11 -> 120000000 | F6: ='Integration Inputs'!C12 -> 8500000 | G6: ='Integration Inputs'!C13 -> 12500000 | H6: ='Integration Inputs'!C14 -> 49500000 | I6: ='Integration Inputs'!C15 -> 1000000 | J6: ='Integration Inputs'!C16 -> 1000000
B7: 1997-98 | C7: 52.6858 | D7: -0.0094893226 | E7: =E6*(1+($D7/100)) -> 1.1998861e+08 | F7: =F6*(1+($D7/100)) -> 8499193.4 | G7: =G6*(1+($D7/100)) -> 12498814 | H7: =H6*(1+($D7/100)) -> 49495303 | I7: =I6*(1+($D7/100)) -> 999905.11 | J7: =J6*(1+($D7/100)) -> 999905.11
B8: 1998-99 | C8: 53.4132 | D8: 1.3806377 | E8: =E7*(1+($D8/100)) -> 1.2164522e+08 | F8: =F7*(1+($D8/100)) -> 8616536.5 | G8: =G7*(1+($D8/100)) -> 12671377 | H8: =H7*(1+($D8/100)) -> 50178654 | I8: =I7*(1+($D8/100)) -> 1013710.2 | J8: =J7*(1+($D8/100)) -> 1013710.2
B9: 1999-00 | C9: 54.1182 | D9: 1.3198985 | E9: =E8*(1+($D9/100)) -> 1.2325081e+08 | F9: =F8*(1+($D9/100)) -> 8730266 | G9: =G8*(1+($D9/100)) -> 12838626 | H9: =H8*(1+($D9/100)) -> 50840961 | I9: =I8*(1+($D9/100)) -> 1027090.1 | J9: =J8*(1+($D9/100)) -> 1027090.1
B10: 2000-01 | C10: 54.6511 | D10: 0.98469646 | E10: =E9*(1+($D10/100)) -> 1.2446446e+08 | F10: =F9*(1+($D10/100)) -> 8816232.6 | G10: =G9*(1+($D10/100)) -> 12965048 | H10: =H9*(1+($D10/100)) -> 51341590 | I10: =I9*(1+($D10/100)) -> 1037203.8 | J10: =J9*(1+($D10/100)) -> 1037203.8
B11: 2001-02 | C11: 55.6035 | D11: 1.7426914 | E11: =E10*(1+($D11/100)) -> 1.2663349e+08 | F11: =F10*(1+($D11/100)) -> 8969872.3 | G11: =G10*(1+($D11/100)) -> 13190989 | H11: =H10*(1+($D11/100)) -> 52236315 | I11: =I10*(1+($D11/100)) -> 1055279.1 | J11: =J10*(1+($D11/100)) -> 1055279.1
B12: 2002-03 | C12: 56.8499 | D12: 2.2415855 | E12: =E11*(1+($D12/100)) -> 1.2947209e+08 | F12: =F11*(1+($D12/100)) -> 9170939.7 | G12: =G11*(1+($D12/100)) -> 13486676 | H12: =H11*(1+($D12/100)) -> 53407237 | I12: =I11*(1+($D12/100)) -> 1078934.1 | J12: =J11*(1+($D12/100)) -> 1078934.1
B13: 2003-04 | C13: 58.1359 | D13: 2.2620972 | E13: =E12*(1+($D13/100)) -> 1.3240087e+08 | F13: =F12*(1+($D13/100)) -> 9378395.3 | G13: =G12*(1+($D13/100)) -> 13791758 | H13: =H12*(1+($D13/100)) -> 54615361 | I13: =I12*(1+($D13/100)) -> 1103340.6 | J13: =J12*(1+($D13/100)) -> 1103340.6
B14: 2004-05 | C14: 59.8765 | D14: 2.9940192 | E14: =E13*(1+($D14/100)) -> 1.3636498e+08 | F14: =F13*(1+($D14/100)) -> 9659186.2 | G14: =G13*(1+($D14/100)) -> 14204686 | H14: =H13*(1+($D14/100)) -> 56250555 | I14: =I13*(1+($D14/100)) -> 1136374.9 | J14: =J13*(1+($D14/100)) -> 1136374.9
B15: 2005-06 | C15: 61.5117 | D15: 2.7309545 | E15: =E14*(1+($D15/100)) -> 1.4008905e+08 | F15: =F14*(1+($D15/100)) -> 9922974.2 | G15: =G14*(1+($D15/100)) -> 14592609 | H15: =H14*(1+($D15/100)) -> 57786732 | I15: =I14*(1+($D15/100)) -> 1167408.7 | J15: =J14*(1+($D15/100)) -> 1167408.7
B16: 2006-07 | C16: 63.1664 | D16: 2.6900573 | E16: =E15*(1+($D16/100)) -> 1.4385752e+08 | F16: =F15*(1+($D16/100)) -> 10189908 | G16: =G15*(1+($D16/100)) -> 14985159 | H16: =H15*(1+($D16/100)) -> 59341228 | I16: =I15*(1+($D16/100)) -> 1198812.7 | J16: =J15*(1+($D16/100)) -> 1198812.7
B17: 2007-08 | C17: 64.6979 | D17: 2.4245485 | E17: =E16*(1+($D17/100)) -> 1.4734542e+08 | F17: =F16*(1+($D17/100)) -> 10436967 | G17: =G16*(1+($D17/100)) -> 15348481 | H17: =H16*(1+($D17/100)) -> 60779985 | I17: =I16*(1+($D17/100)) -> 1227878.5 | J17: =J16*(1+($D17/100)) -> 1227878.5
B18: 2008-09 | C18: 67.0377 | D18: 3.6165007 | E18: =E17*(1+($D18/100)) -> 1.5267417e+08 | F18: =F17*(1+($D18/100)) -> 10814420 | G18: =G17*(1+($D18/100)) -> 15903559 | H18: =H17*(1+($D18/100)) -> 62978094 | I18: =I17*(1+($D18/100)) -> 1272284.7 | J18: =J17*(1+($D18/100)) -> 1272284.7
... B34: 2024-25 | C34: 100 | D34: 4.0685604 | E34: =E33*(1+($D34/100)) -> 2.2774374e+08 | F34: =F33*(1+($D34/100)) -> 16131848 | G34: =G33*(1+($D34/100)) -> 23723307 | H34: =H33*(1+($D34/100)) -> 93944294 | I34: =I33*(1+($D34/100)) -> 1897864.5 | J34: =J33*(1+($D34/100)) -> 1897864.5
C36: OUTPUT USED BY INTEGRATION PAGE: | D36: ='Integration Inputs'!H39 -> 2023-24 | E36: =VLOOKUP(D36,B6:J34,4)*VLOOKUP(D36,B43:D69,3) -> 2.584344e+08 | F36: =VLOOKUP(D36,B6:J34,5)*VLOOKUP(D36,B43:D69,3) -> 18305770 | G36: =VLOOKUP(D36,B6:J34,6)*VLOOKUP(D36,B43:D69,3) -> 26920250 | H36: =VLOOKUP(D36,B6:J34,7)*VLOOKUP(D36,B43:D69,3) -> 1.0660419e+08 | I36: =VLOOKUP(D36,B6:J34,8)*VLOOKUP(D36,B43:D69,3) -> 2153620 | J36: =VLOOKUP(D36,B6:J34,9)*VLOOKUP(D36,B43:D69,3) -> 2153620
C40: Source: | D40: https://www.ofx.com/en-gb/forex-news/historical-exchange-rates/ | H40: 45896
B43: 1998-99 | C43: £ to Euros 1999 | D43: 1.51912
B44: 1999-00 | C44: £ to Euros 2000 | D44: 1.64254
B45: 2000-01 | C45: £ to Euros 2001 | D45: 1.60905
B46: 2001-02 | C46: £ to Euros 2002 | D46: 1.59165
B47: 2002-03 | C47: £ to Euros 2003 | D47: 1.44615
B48: 2003-04 | C48: £ to Euros 2004 | D48: 1.47477
B49: 2004-05 | C49: £ to Euros 2005 | D49: 1.46081
B50: 2005-06 | C50: £ to Euros 2006 | D50: 1.466612
B51: 2006-07 | C51: £ to Euros 2007 | D51: 1.461786
B52: 2007-08 | C52: £ to Euros 2008 | D52: 1.259467
B53: 2008-09 | C53: £ to Euros 2009 | D53: 1.12246
B54: 2009-10 | C54: £ to Euros 2010 | D54: 1.165737
... B69: 2024-25 | C69: £ to Euros 2025 | D69: 1.178907

Sheet US Deflator
B2: Source: | C2: https://www.gpo.gov/fdsys/search/search.action?na=__publishdatehier&se=__2017false&sm=&flr=&ercode=&dateBrowse=&govAuthBrowse=&collection=&historical=false&st=GDP+deflators&psh=&sbh=&tfh=&originalSearch=GDP+deflators&fromState=&sb=re&ps=10&sb=re&ps=10
B4: GDP deflator at market prices
B5: Financial Year | C5: 2009=100 | D5: % change on previous year | E5: ='Integration Inputs'!B11 -> Pesticides in sources of drinking water | F5: ='Integration Inputs'!B12 -> Pollution incidents, fish deaths and monitoring costs | G5: ='Integration Inputs'!B13 -> Biodiversity/wildlife losses | H5: ='Integration Inputs'!B14 -> Cultural, landscape, toursim etc. (Hedgerow and dry stone walls) | I5: ='Integration Inputs'!B15 -> Bee colony losses | J5: ='Integration Inputs'!B16 -> Acute effects of pesticides to human health
B6: 1996-97 | C6: 68.164 | D6: 1.8300244 | E6: ='Integration Inputs'!E11*D39 -> 9.2492896e+08 | F6: ='Integration Inputs'!E12*D39 -> 1.328023e+08 | G6: ='Integration Inputs'!E13*D39 -> 170299420 | H6: ='Integration Inputs'!E14*D39 -> 0 | I6: ='Integration Inputs'!E15*D39 -> 1.1874088e+08 | J6: ='Integration Inputs'!E16*D39 -> 137489440
B7: 1997-98 | C7: 69.34 | D7: 1.7252509 | E7: =E6*(1+($D7/100)) -> 9.408863e+08 | F7: =F6*(1+($D7/100)) -> 1.3509347e+08 | G7: =G6*(1+($D7/100)) -> 1.7323751e+08 | H7: =H6*(1+($D7/100)) -> 0 | I7: =I6*(1+($D7/100)) -> 1.2078946e+08 | J7: =J6*(1+($D7/100)) -> 1.3986148e+08
B8: 1998-99 | C8: 70.119 | D8: 1.1234497 | E8: =E7*(1+($D8/100)) -> 9.5145669e+08 | F8: =F7*(1+($D8/100)) -> 1.3661118e+08 | G8: =G7*(1+($D8/100)) -> 1.7518375e+08 | H8: =H7*(1+($D8/100)) -> 0 | I8: =I7*(1+($D8/100)) -> 1.2214647e+08 | J8: =J7*(1+($D8/100)) -> 1.4143275e+08
B9: 1999-00 | C9: 71.111 | D9: 1.4147378 | E9: =E8*(1+($D9/100)) -> 9.6491731e+08 | F9: =F8*(1+($D9/100)) -> 1.3854387e+08 | G9: =G8*(1+($D9/100)) -> 1.7766214e+08 | H9: =H8*(1+($D9/100)) -> 0 | I9: =I8*(1+($D9/100)) -> 1.2387452e+08 | J9: =J8*(1+($D9/100)) -> 1.4343365e+08
B10: 2000-01 | C10: 72.722 | D10: 2.2654723 | E10: =E9*(1+($D10/100)) -> 9.8677724e+08 | F10: =F9*(1+($D10/100)) -> 1.4168254e+08 | G10: =G9*(1+($D10/100)) -> 1.8168703e+08 | H10: =H9*(1+($D10/100)) -> 0 | I10: =I9*(1+($D10/100)) -> 1.2668086e+08 | J10: =J9*(1+($D10/100)) -> 1.466831e+08
B11: 2001-02 | C11: 74.36 | D11: 2.2524133 | E11: =E10*(1+($D11/100)) -> 1.0090035e+09 | F11: =F10*(1+($D11/100)) -> 1.4487382e+08 | G11: =G10*(1+($D11/100)) -> 1.8577937e+08 | H11: =H10*(1+($D11/100)) -> 0 | I11: =I10*(1+($D11/100)) -> 1.2953424e+08 | J11: =J10*(1+($D11/100)) -> 1.4998701e+08
B12: 2002-03 | C12: 75.515 | D12: 1.5532544 | E12: =E11*(1+($D12/100)) -> 1.0246759e+09 | F12: =F11*(1+($D12/100)) -> 1.4712408e+08 | G12: =G11*(1+($D12/100)) -> 1.8866499e+08 | H12: =H11*(1+($D12/100)) -> 0 | I12: =I11*(1+($D12/100)) -> 1.3154623e+08 | J12: =J11*(1+($D12/100)) -> 1.5231669e+08
B13: 2003-04 | C13: 77.006 | D13: 1.9744422 | E13: =E12*(1+($D13/100)) -> 1.0449076e+09 | F13: =F12*(1+($D13/100)) -> 1.5002896e+08 | G13: =G12*(1+($D13/100)) -> 1.9239008e+08 | H13: =H12*(1+($D13/100)) -> 0 | I13: =I12*(1+($D13/100)) -> 1.3414354e+08 | J13: =J12*(1+($D13/100)) -> 1.553241e+08
B14: 2004-05 | C14: 79.077 | D14: 2.6894008 | E14: =E13*(1+($D14/100)) -> 1.0730093e+09 | F14: =F13*(1+($D14/100)) -> 1.5406384e+08 | G14: =G13*(1+($D14/100)) -> 1.9756422e+08 | H14: =H13*(1+($D14/100)) -> 0 | I14: =I13*(1+($D14/100)) -> 1.377512e+08 | J14: =J13*(1+($D14/100)) -> 1.5950139e+08
B15: 2005-06 | C15: 81.556 | D15: 3.1349191 | E15: =E14*(1+($D15/100)) -> 1.1066473e+09 | F15: =F14*(1+($D15/100)) -> 1.5889362e+08 | G15: =G14*(1+($D15/100)) -> 2.0375769e+08 | H15: =H14*(1+($D15/100)) -> 0 | I15: =I14*(1+($D15/100)) -> 1.4206959e+08 | J15: =J14*(1+($D15/100)) -> 1.6450163e+08
B16: 2006-07 | C16: 84.071 | D16: 3.0837707 | E16: =E15*(1+($D16/100)) -> 1.1407738e+09 | F16: =F15*(1+($D16/100)) -> 1.6379353e+08 | G16: =G15*(1+($D16/100)) -> 2.1004111e+08 | H16: =H15*(1+($D16/100)) -> 0 | I16: =I15*(1+($D16/100)) -> 1.4645069e+08 | J16: =J15*(1+($D16/100)) -> 1.6957448e+08
B17: 2007-08 | C17: 86.349 | D17: 2.7096145 | E17: =E16*(1+($D17/100)) -> 1.1716843e+09 | F17: =F16*(1+($D17/100)) -> 1.682317e+08 | G17: =G16*(1+($D17/100)) -> 2.1573242e+08 | H17: =H16*(1+($D17/100)) -> 0 | I17: =I16*(1+($D17/100)) -> 1.5041893e+08 | J17: =J16*(1+($D17/100)) -> 1.7416929e+08
B18: 2008-09 | C18: 88.013 | D18: 1.9270634 | E18: =E17*(1+($D18/100)) -> 1.1942634e+09 | F18: =F17*(1+($D18/100)) -> 1.7147363e+08 | G18: =G17*(1+($D18/100)) -> 2.1988972e+08 | H18: =H17*(1+($D18/100)) -> 0 | I18: =I17*(1+($D18/100)) -> 1.533176e+08 | J18: =J17*(1+($D18/100)) -> 1.7752565e+08
... B34: 2024-25 | C34: 125.23 | D34: 2.4183589 | E34: =E33*(1+($D34/100)) -> 1.6992673e+09 | F34: =F33*(1+($D34/100)) -> 2.4398263e+08 | G34: =G33*(1+($D34/100)) -> 3.1287184e+08 | H34: =H33*(1+($D34/100)) -> 0 | I34: =I33*(1+($D34/100)) -> 2.1814918e+08 | J34: =J33*(1+($D34/100)) -> 2.5259378e+08
C36: OUTPUT USED BY INTEGRATION PAGE: | D36: ='Integration Inputs'!H39 -> 2023-24 | E36: =VLOOKUP(D36,B6:J34,4)*VLOOKUP(D36,B41:D67,3) -> 1.5335229e+09 | F36: =VLOOKUP(D36,B6:J34,5)*VLOOKUP(D36,B41:D67,3) -> 2.2018487e+08 | G36: =VLOOKUP(D36,B6:J34,6)*VLOOKUP(D36,B41:D67,3) -> 2.8235471e+08 | H36: =VLOOKUP(D36,B6:J34,7)*VLOOKUP(D36,B41:D67,3) -> 0 | I36: =VLOOKUP(D36,B6:J34,8)*VLOOKUP(D36,B41:D67,3) -> 1.9687118e+08 | J36: =VLOOKUP(D36,B6:J34,9)*VLOOKUP(D36,B41:D67,3) -> 2.279561e+08
C38: Source: | D38: https://www.ofx.com/en-gb/forex-news/historical-exchange-rates/ | H38: 45894
C39: £ to USD Average 1996 | D39: 1.56238
B41: 1998-99 | C41: $ to Euro 1999 | D41: 0.939283
B42: 1999-00 | C42: $ to Euro 2000 | D42: 1.085947
B43: 2000-01 | C43: $ to Euro 2001 | D43: 1.117082
B44: 2001-02 | C44: $ to Euro 2002 | D44: 1.064385
B45: 2002-03 | C45: $ to Euro 2003 | D45: 0.883383
B46: 2003-04 | C46: $ to Euro 2004 | D46: 0.80471
B47: 2004-05 | C47: $ to Euro 2005 | D47: 0.803857
B48: 2005-06 | C48: $ to Euro 2006 | D48: 0.796727
B49: 2006-07 | C49: $ to Euro 2007 | D49: 0.730785
B50: 2007-08 | C50: $ to Euro 2008 | D50: 0.683075
B51: 2008-09 | C51: $ to Euro 2009 | D51: 0.719039
B52: 2009-10 | C52: $ to Euro 2010 | D52: 0.754908
... B67: 2024-25 | C67: $ to Euro 2025 | D67: 0.901311

Sheet German Deflator
B2: Source: | C2: http://data.worldbank.org/indicator/NY.GDP.DEFL.KD.ZG
B4: GDP deflator at market prices
B5: Financial Year | D5: % change on previous year | E5: ='Integration Inputs'!B11 -> Pesticides in sources of drinking water | F5: ='Integration Inputs'!B12 -> Pollution incidents, fish deaths and monitoring costs | G5: ='Integration Inputs'!B13 -> Biodiversity/wildlife losses | H5: ='Integration Inputs'!B14 -> Cultural, landscape, toursim etc. (Hedgerow and dry stone walls) | I5: ='Integration Inputs'!B15 -> Bee colony losses | J5: ='Integration Inputs'!B16 -> Acute effects of pesticides to human health
B6: 1996-97 | C6: 74.7 | D6: 0.1 | E6: ='Integration Inputs'!G11*D41 -> 136370180 | F6: ='Integration Inputs'!G12*D41 -> 38794965 | G6: ='Integration Inputs'!G13*D41 -> 4702420 | H6: ='Integration Inputs'!G14*D41 -> 0 | I6: ='Integration Inputs'!G15*D41 -> 1175605 | J6: ='Integration Inputs'!G16*D41 -> 21160890
B7: 1997-98 | C7: 75.2 | D7: 0.7 | E7: =E6*(1+($D7/100)) -> 1.3732477e+08 | F7: =F6*(1+($D7/100)) -> 39066530 | G7: =G6*(1+($D7/100)) -> 4735336.9 | H7: =H6*(1+($D7/100)) -> 0 | I7: =I6*(1+($D7/100)) -> 1183834.2 | J7: =J6*(1+($D7/100)) -> 21309016
B8: 1998-99 | C8: 75.6 | D8: 0.6 | E8: =E7*(1+($D8/100)) -> 1.3814872e+08 | F8: =F7*(1+($D8/100)) -> 39300929 | G8: =G7*(1+($D8/100)) -> 4763749 | H8: =H7*(1+($D8/100)) -> 0 | I8: =I7*(1+($D8/100)) -> 1190937.2 | J8: =J7*(1+($D8/100)) -> 21436870
B9: 1999-00 | C9: 75.3 | D9: -0.3 | E9: =E8*(1+($D9/100)) -> 1.3773427e+08 | F9: =F8*(1+($D9/100)) -> 39183026 | G9: =G8*(1+($D9/100)) -> 4749457.7 | H9: =H8*(1+($D9/100)) -> 0 | I9: =I8*(1+($D9/100)) -> 1187364.4 | J9: =J8*(1+($D9/100)) -> 21372560
B10: 2000-01 | C10: 76.4 | D10: 1.4 | E10: =E9*(1+($D10/100)) -> 1.3966255e+08 | F10: =F9*(1+($D10/100)) -> 39731589 | G10: =G9*(1+($D10/100)) -> 4815950.1 | H10: =H9*(1+($D10/100)) -> 0 | I10: =I9*(1+($D10/100)) -> 1203987.5 | J10: =J9*(1+($D10/100)) -> 21671776
B11: 2001-02 | C11: 77.6 | D11: 1.5 | E11: =E10*(1+($D11/100)) -> 1.4175749e+08 | F11: =F10*(1+($D11/100)) -> 40327562 | G11: =G10*(1+($D11/100)) -> 4888189.4 | H11: =H10*(1+($D11/100)) -> 0 | I11: =I10*(1+($D11/100)) -> 1222047.3 | J11: =J10*(1+($D11/100)) -> 21996852
B12: 2002-03 | C12: 78.6 | D12: 1.3 | E12: =E11*(1+($D12/100)) -> 1.4360034e+08 | F12: =F11*(1+($D12/100)) -> 40851821 | G12: =G11*(1+($D12/100)) -> 4951735.8 | H12: =H11*(1+($D12/100)) -> 0 | I12: =I11*(1+($D12/100)) -> 1237934 | J12: =J11*(1+($D12/100)) -> 22282811
B13: 2003-04 | C13: 79.5 | D13: 1.2 | E13: =E12*(1+($D13/100)) -> 1.4532354e+08 | F13: =F12*(1+($D13/100)) -> 41342042 | G13: =G12*(1+($D13/100)) -> 5011156.7 | H13: =H12*(1+($D13/100)) -> 0 | I13: =I12*(1+($D13/100)) -> 1252789.2 | J13: =J12*(1+($D13/100)) -> 22550205
B14: 2004-05 | C14: 79.9 | D14: 0.5 | E14: =E13*(1+($D14/100)) -> 1.4605016e+08 | F14: =F13*(1+($D14/100)) -> 41548753 | G14: =G13*(1+($D14/100)) -> 5036212.4 | H14: =H13*(1+($D14/100)) -> 0 | I14: =I13*(1+($D14/100)) -> 1259053.1 | J14: =J13*(1+($D14/100)) -> 22662956
B15: 2005-06 | C15: 80.3 | D15: 0.4 | E15: =E14*(1+($D15/100)) -> 1.4663436e+08 | F15: =F14*(1+($D15/100)) -> 41714948 | G15: =G14*(1+($D15/100)) -> 5056357.3 | H15: =H14*(1+($D15/100)) -> 0 | I15: =I14*(1+($D15/100)) -> 1264089.3 | J15: =J14*(1+($D15/100)) -> 22753608
B16: 2006-07 | C16: 81.8 | D16: 1.8 | E16: =E15*(1+($D16/100)) -> 1.4927378e+08 | F16: =F15*(1+($D16/100)) -> 42465817 | G16: =G15*(1+($D16/100)) -> 5147371.7 | H16: =H15*(1+($D16/100)) -> 0 | I16: =I15*(1+($D16/100)) -> 1286842.9 | J16: =J15*(1+($D16/100)) -> 23163173
B17: 2007-08 | C17: 82.5 | D17: 1 | E17: =E16*(1+($D17/100)) -> 1.5076652e+08 | F17: =F16*(1+($D17/100)) -> 42890475 | G17: =G16*(1+($D17/100)) -> 5198845.4 | H17: =H16*(1+($D17/100)) -> 0 | I17: =I16*(1+($D17/100)) -> 1299711.4 | J17: =J16*(1+($D17/100)) -> 23394805
B18: 2008-09 | C18: 84.2 | D18: 2 | E18: =E17*(1+($D18/100)) -> 1.5378185e+08 | F18: =F17*(1+($D18/100)) -> 43748284 | G18: =G17*(1+($D18/100)) -> 5302822.4 | H18: =H17*(1+($D18/100)) -> 0 | I18: =I17*(1+($D18/100)) -> 1325705.6 | J18: =J17*(1+($D18/100)) -> 23862701
... B33: 2023-24 | C33: 120.2 | D33: 3.1 | E33: =E32*(1+($D33/100)) -> 2.1967524e+08 | F33: =F32*(1+($D33/100)) -> 62493817 | G33: =G32*(1+($D33/100)) -> 7575008.1 | H33: =H32*(1+($D33/100)) -> 0 | I33: =I32*(1+($D33/100)) -> 1893752 | J33: =J32*(1+($D33/100)) -> 34087537
C36: OUTPUT USED BY INTEGRATION PAGE: | D36: ='Integration Inputs'!H39 -> 2023-24 | E36: =VLOOKUP(D36,B6:J33,4)*VLOOKUP(D36,B43:D61,3) -> 2.1967524e+08 | F36: =VLOOKUP(D36,B6:J33,5)*VLOOKUP(D36,B43:D61,3) -> 62493817 | G36: =VLOOKUP(D36,B6:J33,6)*VLOOKUP(D36,B43:D61,3) -> 7575008.1 | H36: =VLOOKUP(D36,B6:J33,7)*VLOOKUP(D36,B43:D61,3) -> 0 | I36: =VLOOKUP(D36,B6:J33,8)*VLOOKUP(D36,B43:D61,3) -> 1893752 | J36: =VLOOKUP(D36,B6:J33,9)*VLOOKUP(D36,B43:D61,3) -> 34087537
C40: Source: | D40: http://www.oanda.com/convert/fxhistory
C41: £ to DM Average 1996 | D41: 2.35121
B43: =B8 -> 1998-99 | C43: DM to Euro 1999 | D43: 0.51131
B44: =B9 -> 1999-00 | C44: DM to Euro 2000 | D44: 0.51131
B45: =B10 -> 2000-01 | C45: DM to Euro 2001 | D45: 0.51131
B46: =B11 -> 2001-02 | C46: Euro 2002 | D46: 1
B47: =B12 -> 2002-03 | C47: Euro 2003 | D47: 1
B48: =B13 -> 2003-04 | C48: Euro 2004 | D48: 1
B49: =B14 -> 2004-05 | C49: Euro 2005 | D49: 1
B50: =B15 -> 2005-06 | C50: Euro 2006 | D50: 1
B51: =B16 -> 2006-07 | C51: Euro 2007 | D51: 1
B52: =B17 -> 2007-08 | C52: Euro 2008 | D52: 1
B53: =B18 -> 2008-09 | C53: Euro 2009 | D53: 1
B54: =B26 -> 2016-17 | C54: Euro 2010 | D54: 1
B55: =B27 -> 2017-18 | C55: Euro 2011 | D55: 1
B56: =B28 -> 2018-19 | C56: Euro 2012 | D56: 1
B57: =B29 -> 2019-20 | C57: Euro 2013 | D57: 1
B58: =B30 -> 2020-21 | C58: Euro 2014 | D58: 1
B59: =B31 -> 2021-22 | C59: Euro 2015 | D59: 1
B60: =B32 -> 2022-23 | C60: Euro 2016 | D60: 1
B61: =B33 -> 2023-24 | C61: Euro 2017 | D61: 1

Sheet Chemical EIQ and Costs
B1: Environmental Impact Quotient - EIQ with Adjusted Integrated Costs from Pretty et al. 2001
B2: Kovach, J., Petzoldt, C., Degnil, J. and Tette, J. (1992) New York's Food and Life Sci. Bull. 139:1-8
B4: Most of the data to EIQ assessment is available at: | D4: http://sitem.herts.ac.uk/aeru/footprint/en/index.htm
B7: 1). | I7: Mode of action | L7: Toxicity to fish - 96hr LC50
C8: http://sitem.herts.ac.uk/aeru/footprint/en/index.htm | I8: Non systemic | J8: 1 | L8: >100 ppm | M8: 1
C9: Enter name of pesticde for EIQ evaluation | D9: Meptyldinocap | I9: All herbicides | J9: 1 | L9: 0.1-100 ppm | M9: 3
C10: SY = systemicity = | D10: Non systemic | E10: =IF(D10=$I$8,$J$8,IF(D10=$I$9,$J$9,IF(D10=$I$10,$J$10,0))) -> 1 | I10: Systemic | J10: 3 | L10: <0.1 ppm | M10: 5
C11: DT = dermal toxicity = | D11: >2000 | E11: =IF(D11=$I$13,$J$13,IF(D11=$I$14,$J$14,IF(D11=$I$15,$J$15,0))) -> 1
C12: CT = chronic toxicity = Reproductive | D12: Little or none | E12: =IF(D12=$I$18,$J$18,IF(D12=$I$19,$J$19,IF(D12=$I$20,$J$20,0))) -> 1 | I12: Acute dermal - LD50 for Rabbits/Rats (mg/kg) | L12: Toxicity to birds - 8 day LC50
C13: CT = chronic toxicity = Teratogenic | D13: Little or none | E13: =IF(D13=$I$18,$J$18,IF(D13=$I$19,$J$19,IF(D13=$I$20,$J$20,0))) -> 1 | I13: >2000 | J13: 1 | L13: >2000 ppm | M13: 1
C14: CT = chronic toxicity = Mutagenic | D14: Possible | E14: =IF(D14=$I$18,$J$18,IF(D14=$I$19,$J$19,IF(D14=$I$20,$J$20,0))) -> 3 | I14: 100-2000 | J14: 3 | L14: 100-2000 ppm | M14: 3
C15: CT = chronic toxicity = Oncogenic | D15: Little or none | E15: =IF(D15=$I$18,$J$18,IF(D15=$I$19,$J$19,IF(D15=$I$20,$J$20,0))) -> 1 | I15: 0-100 | J15: 5 | L15: <100 ppm | M15: 5
C16: SHL = soil half-life = | D16: <30 days | E16: =IF(D16=$I$30,$J$30,IF(D16=$I$31,$J$31,IF(D16=$I$32,$J$32,0))) -> 1
C17: SLP = surface loss potential = | D17: small | E17: =IF(D17=$L$30,$M$30,IF(D17=$L$31,$M$31,IF(D17=$L$32,$M$32,0))) -> 1 | I17: Long-term Health Effects | L17: Toxicity to Bees
C18: LP = leaching potential = | D18: small | E18: =IF(D18=$L$30,$M$30,IF(D18=$L$31,$M$31,IF(D18=$L$32,$M$32,0))) -> 1 | I18: Little or none | J18: 1 | L18: > 100 ug/bee | M18: 1
C19: PSHL = plant surface half-life = | D19: 1-2 weeks | E19: =IF(D19=$I$23,$J$23,IF(D19=$I$24,$J$24,IF(D19=$I$25,$J$25,IF(D19=$I$26,$J$26,IF(D19=$I$27,$J$27,0))))) -> 1 | I19: Possible | J19: 3 | L19: 1-100 ug/bee | M19: 3
C20: BT = bird toxicity = | D20: >2000 ppm | E20: =IF(D20=$L$13,$M$13,IF(D20=$L$14,$M$14,IF(D20=$L$15,$M$15,0))) -> 1 | I20: Definite | J20: 5 | L20: <1 ug/bee | M20: 5
C21: FT = fish toxicity = | D21: <0.1 ppm | E21: =IF(D21=$L$8,$M$8,IF(D21=$L$9,$M$9,IF(D21=$L$10,$M$10,0))) -> 5
C22: ZT = bee toxicity = | D22: 1-100 ug/bee | E22: =IF(D22=$L$18,$M$18,IF(D22=$L$19,$M$19,IF(D22=$L$20,$M$20,0))) -> 3 | I22: Plant surface residues - Half life | L22: Toxicity to Beneficials
C23: BAT = beneficIal arthropod toxicity = | D23: Moderate impact | E23: =IF(D23=$L$23,$M$23,IF(D23=$L$24,$M$24,IF(D23=$L$25,$M$25,0))) -> 3 | F23: No calculable data, used bee tox | I23: 1-2 weeks | J23: 1 | L23: Low impact | M23: 1
I24: 2-4 weeks | J24: 3 | L24: Moderate impact | M24: 3
I25: >4 weeks | J25: 5 | L25: Severe impact | M25: 5
E26: Costs (€ per Kg ai) | F26: Costs per Hectare | I26: Pre-emergent herbicides | J26: 1
C27: Applicator effects | D27: =IF(AND(E11=0,E12=0,E13=0,E14=0,E15=0),0,E11*5*(AVERAGE(E12:E15))) -> 7.5 | E27: =IF(D27=0,0,IF(D27<'Integration Inputs'!$D$76,'Integration Inputs'!$C$91*SUM('Integration Inputs'!$C$63:$H$63),IF(D27<'Integration Inputs'!$F$76,'Integration Inputs'!$D$91*SUM('Integration Inputs'!$C$63:$H$63),'Integration Inputs'!$E$91*SUM('Integration Inputs'!C$63:H$63)))) -> 12.65115 | F27: =E27*D40*D41 -> 0 | I27: Post emergent herbicides | J27: 3
C28: Picker effects | D28: =IF(AND(E11=0,E12=0,E19=0),0,E11*E19*(AVERAGE(E12:E15))) -> 1.5 | E28: =IF(D28=0,0,IF(D28<'Integration Inputs'!$D$77,'Integration Inputs'!$C$91*SUM('Integration Inputs'!$C$64:$H$64),IF(D28<'Integration Inputs'!$F$77,'Integration Inputs'!$D$91*SUM('Integration Inputs'!$C$64:$H$64),'Integration Inputs'!$E$91*SUM('Integration Inputs'!$C$64:$H$64)))) -> 3.2914643 | F28: =E28*D40*D41 -> 0
C29: Consumer effects | D29: =IF(AND(E10=0,E12=0,E13=0,E14=0,E15=0,E16=0,,E19=0),0,(AVERAGE(E12:E15)*((E16+E19)/2)*E10)) -> 1.5 | E29: =IF(D29=0,0,IF(D29<'Integration Inputs'!$D$78,'Integration Inputs'!$C$91*SUM('Integration Inputs'!$C$65:$H$65),IF(D29<'Integration Inputs'!$F$78,'Integration Inputs'!$D$91*SUM('Integration Inputs'!$C$65:$H$65),'Integration Inputs'!$E$91*SUM('Integration Inputs'!$C$65:$H$65)))) -> 0.85186978 | F29: =E29*D40*D41 -> 0 | I29: Soil residue half-life | L29: Groundwater and Runoff Potential
C30: Ground water leaching | D30: =IF(E18=0,0,E18) -> 1 | E30: =IF(D30=0,0,IF(D30<'Integration Inputs'!$D$79,'Integration Inputs'!$C$91*SUM('Integration Inputs'!$C$66:$H$66),IF(D30<'Integration Inputs'!$F$79,'Integration Inputs'!$D$91*SUM('Integration Inputs'!$C$66:$H$66),'Integration Inputs'!$E$91*SUM('Integration Inputs'!$C$66:$H$66)))) -> 0.97276634 | F30: =E30*D40*D41 -> 0 | I30: <30 days | J30: 1 | L30: small | M30: 1
C31: Aquatic effects | D31: =IF(AND(E21=0,E17=0),0,E21*E17) -> 5 | E31: =IF(D31=0,0,IF(D31<'Integration Inputs'!$D$80,'Integration Inputs'!$C$91*SUM('Integration Inputs'!$C$67:$H$67),IF(D31<'Integration Inputs'!$F$80,'Integration Inputs'!$D$91*SUM('Integration Inputs'!$C$67:$H$67),'Integration Inputs'!$E$91*SUM('Integration Inputs'!$C$67:$H$67)))) -> 0 | F31: =E31*D40*D41 -> 0 | I31: 30-100 days | J31: 3 | L31: medium | M31: 3
C32: Bird effects | D32: =IF(AND(E16=0,E19=0,E20=0),0,E20*((E16+E19)/2)*3) -> 3 | E32: =IF(D32=0,0,IF(D32<'Integration Inputs'!$D$81,'Integration Inputs'!$C$91*SUM('Integration Inputs'!$C$68:$H$68),IF(D32<'Integration Inputs'!$F$81,'Integration Inputs'!$D$91*SUM('Integration Inputs'!$C$68:$H$68),'Integration Inputs'!$E$91*SUM('Integration Inputs'!$C$68:$H$68)))) -> 0 | F32: =E32*D40*D41 -> 0 | I32: >100 days | J32: 5 | L32: large | M32: 5
C33: Bee effects | D33: =IF(AND(E19=0,E22=0),0,E22*E19*3) -> 9 | E33: =IF(D33=0,0,IF(D33<'Integration Inputs'!$D$82,'Integration Inputs'!$C$91*SUM('Integration Inputs'!$C$69:$H$69),IF(D33<'Integration Inputs'!$F$82,'Integration Inputs'!$D$91*SUM('Integration Inputs'!$C$69:$H$69),'Integration Inputs'!$E$91*SUM('Integration Inputs'!$C$69:$H$69)))) -> 0 | F33: =E33*D40*D41 -> 0
C34: Beneficials effects | D34: =IF(AND(E19=0,E23=0),0,(E23*E19*5)) -> 15 | E34: =IF(D34=0,0,IF(D34<'Integration Inputs'!$D$83,'Integration Inputs'!$C$91*SUM('Integration Inputs'!$C$70:$H$70),IF(D34<'Integration Inputs'!$F$83,'Integration Inputs'!$D$91*SUM('Integration Inputs'!$C$70:$H$70),'Integration Inputs'!$E$91*SUM('Integration Inputs'!$C$70:$H$70)))) -> 0 | F34: =E34*D40*D41 -> 0
C35: Farmworker component | D35: =SUM(D27:D28) -> 9 | E35: =SUM(E27:E28) -> 15.942614 | F35: =SUM(F27:F28) -> 0
C36: Consumer component | D36: =SUM(D29:D30) -> 2.5 | E36: =SUM(E29:E30) -> 1.8246361 | F36: =SUM(F29:F30) -> 0
C37: Ecological component | D37: =SUM(D31:D34) -> 32 | E37: =SUM(E31:E34) -> 0 | F37: =SUM(F31:F34) -> 0
E38: =SUM(E27:E34) -> 17.76725 | F38: =SUM(F27:F34) -> 0
C39: EIQ = | D39: =(AVERAGE(E12:E15)*((E11*5)+(E11*E19))+((AVERAGE(E12:E15)*((E16+E19)/2)*E10)+(E18))+((E21*E17)+(E20*((E16+E19)/2)*3)+(E22*E19*3)+(E23*E19*5)))/3 -> 14.5
C40: % active ingredient
C41: Rate (Kg of formulation per hectare)
C42: EIQ Field Use Rating = | D42: =D39*D40*D41 -> 0 | E42: =SUM(F27:F34) -> 0 | F42: of secondary damage per hectare
B44: =LEFT(B7,1)+1&")." -> 2).
...

Sheet GDP Pop Data
B1: GDP and Population Data
B2: http://en.wikipedia.org/wiki/List_of_countries_by_GDP_%28PPP%29
B5: Country | C5: GDP millions (USD) | D5: Population | E5: % GDP from Agriculture | F5: % Labour force in agricuture | G5: GDP per capita (USD) | H5: % of Weighted UK, US & German GDP per capita | I5: Multiple of weighted UK, US and Germany % GDP from Agriculture | K5: Multiple of weighted UK, US and Germany % Labour force in Agriculture
B6: Absolute costs | H6: =G228/G228 -> 1 | I6: =G229/G229 -> 1 | K6: =F41/F$41 -> #DIV/0!
B7: Afghanistan | C7: 82007.333 | D7: 42650000 | E7: 0.347 | G7: =C7/D7*1000000 -> 1922.798 | H7: =G7/G$228 -> 0.024700448 | I7: =IFERROR(E7/G$229,"-") -> 40.687934
B8: Albania | C8: 59400.333 | D8: 2790000 | E8: 0.155 | G8: =C8/D8*1000000 -> 21290.442 | H8: =G8/G$228 -> 0.27349907 | I8: =IFERROR(E8/G$229,"-") -> 18.174726
B9: Algeria | C9: 806655.67 | D9: 46810000 | E9: 0.131 | G9: =C9/D9*1000000 -> 17232.55 | H9: =G9/G$228 -> 0.221371 | I9: =IFERROR(E9/G$229,"-") -> 15.360575
B10: Andorra | C10: 5988.3333 | D10: 80000 | E10: 0.005 | G10: =C10/D10*1000000 -> 74854.167 | H10: =G10/G$228 -> 0.96158383 | I10: =IFERROR(E10/G$229,"-") -> 0.58628147
B11: Angola | C11: 332221 | D11: 37890000 | E11: 0.164 | G11: =C11/D11*1000000 -> 8768.0391 | H11: =G11/G$228 -> 0.11263507 | I11: =IFERROR(E11/G$229,"-") -> 19.230032
B12: Antigua and Barbuda | C12: 3085.3333 | D12: 90000 | E12: 0.019 | G12: =C12/D12*1000000 -> 34281.481 | H12: =G12/G$228 -> 0.44038321 | I12: =IFERROR(E12/G$229,"-") -> 2.2278696
B13: Argentina | C13: 1361776.3 | D13: 45700000 | E13: 0.06 | G13: =C13/D13*1000000 -> 29798.169 | H13: =G13/G$228 -> 0.38279015 | I13: =IFERROR(E13/G$229,"-") -> 7.0353776
B14: Armenia | C14: 68145.667 | D14: 2970000 | E14: 0.079 | G14: =C14/D14*1000000 -> 22944.669 | H14: =G14/G$228 -> 0.29474942 | I14: =IFERROR(E14/G$229,"-") -> 9.2632472
B15: Aruba | C15: 4900.6667 | D15: 110000 | E15: 0 | G15: =C15/D15*1000000 -> 44551.515 | H15: =G15/G$228 -> 0.57231305 | I15: =IFERROR(E15/G$229,"-") -> 0
B16: Australia | C16: 1850606.7 | D16: 26710000 | E16: 0.022 | G16: =C16/D16*1000000 -> 69285.162 | H16: =G16/G$228 -> 0.89004385 | I16: =IFERROR(E16/G$229,"-") -> 2.5796385
B17: Austria | C17: 640445.33 | D17: 9120000 | E17: 0.012 | G17: =C17/D17*1000000 -> 70224.269 | H17: =G17/G$228 -> 0.90210772 | I17: =IFERROR(E17/G$229,"-") -> 1.4070755
B18: Azerbaijan | C18: 251092.33 | D18: 10340000 | E18: 0.057 | G18: =C18/D18*1000000 -> 24283.591 | H18: =G18/G$228 -> 0.31194935 | I18: =IFERROR(E18/G$229,"-") -> 6.6836088
... B72: France | C72: 4145781 | D72: 66550000 | E72: 0.014 | G72: =C72/D72*1000000 -> 62295.733 | H72: =G72/G$228 -> 0.80025697 | I72: =IFERROR(E72/G$229,"-") -> 1.6415881
B73: French Guiana | D73: 310000 | G73: =C73/D73*1000000 -> 0 | H73: =G73/G$228 -> 0 | I73: =IFERROR(E73/G$229,"-") -> 0
B74: French Polynesia | D74: 280000 | E74: 0.022 | G74: =C74/D74*1000000 -> 0 | H74: =G74/G$228 -> 0 | I74: =IFERROR(E74/G$229,"-") -> 2.5796385
B75: Gabon | C75: 53367.333 | D75: 2540000 | E75: 0.062 | G75: =C75/D75*1000000 -> 21010.761 | H75: =G75/G$228 -> 0.26990626 | I75: =IFERROR(E75/G$229,"-") -> 7.2698902
B76: Gambia | C76: 9406.3333 | D76: 2760000 | E76: 0.241 | G76: =C76/D76*1000000 -> 3408.0918 | H76: =G76/G$228 -> 0.043780675 | I76: =IFERROR(E76/G$229,"-") -> 28.258767
B77: Georgia | C77: 103278.33 | D77: 3810000 | E77: 0.054 | G77: =C77/D77*1000000 -> 27107.174 | H77: =G77/G$228 -> 0.34822137 | I77: =IFERROR(E77/G$229,"-") -> 6.3318399
B78: Germany | C78: 5815284.7 | D78: 84550000 | E78: 0.008 | G78: =C78/D78*1000000 -> 68779.239 | H78: =G78/G$228 -> 0.88354472 | I78: =IFERROR(E78/G$229,"-") -> 0.93805035
B79: Ghana | C79: 271532.33 | D79: 34430000 | E79: 0.207 | G79: =C79/D79*1000000 -> 7886.504 | H79: =G79/G$228 -> 0.10131079 | I79: =IFERROR(E79/G$229,"-") -> 24.272053
B80: Greece | C80: 439224.67 | D80: 10050000 | E80: 0.033 | G80: =C80/D80*1000000 -> 43703.947 | H80: =G80/G$228 -> 0.56142511 | I80: =IFERROR(E80/G$229,"-") -> 3.8694577
B81: Greenland | C81: 4261.5 | D81: 60000 | E81: 0.166 | G81: =C81/D81*1000000 -> 71025 | H81: =G81/G$228 -> 0.91239398 | I81: =IFERROR(E81/G$229,"-") -> 19.464545
B82: Grenada | C82: 2321.3333 | D82: 120000 | E82: 0.027 | G82: =C82/D82*1000000 -> 19344.444 | H82: =G82/G$228 -> 0.24850059 | I82: =IFERROR(E82/G$229,"-") -> 3.1659199
B83: Guadeloupe | D83: 380000 | G83: =C83/D83*1000000 -> 0 | H83: =G83/G$228 -> 0 | I83: =IFERROR(E83/G$229,"-") -> 0
B84: Guam | D84: 170000 | G84: =C84/D84*1000000 -> 0 | H84: =G84/G$228 -> 0 | I84: =IFERROR(E84/G$229,"-") -> 0
B85: Guatemala | C85: 259993.67 | D85: 18410000 | E85: 0.098 | G85: =C85/D85*1000000 -> 14122.415 | H85: =G85/G$228 -> 0.18141791 | I85: =IFERROR(E85/G$229,"-") -> 11.491117
B86: Guinea | C86: 67351.667 | D86: 14750000 | E86: 0.296 | G86: =C86/D86*1000000 -> 4566.2147 | H86: =G86/G$228 -> 0.058658033 | I86: =IFERROR(E86/G$229,"-") -> 34.707863
B87: Guinea-Bissau | C87: 6417.3333 | D87: 2200000 | E87: 0.368 | G87: =C87/D87*1000000 -> 2916.9697 | H87: =G87/G$228 -> 0.037471673 | I87: =IFERROR(E87/G$229,"-") -> 43.150316
B88: Guyana | C88: 66708.667 | D88: 830000 | E88: 0.08 | G88: =C88/D88*1000000 -> 80371.888 | H88: =G88/G$228 -> 1.032465 | I88: =IFERROR(E88/G$229,"-") -> 9.3805035
B89: Haiti | C89: 36215.333 | D89: 11770000 | E89: 0.159 | G89: =C89/D89*1000000 -> 3076.9187 | H89: =G89/G$228 -> 0.039526394 | I89: =IFERROR(E89/G$229,"-") -> 18.643751
B90: Honduras | C90: 79440.667 | D90: 10830000 | E90: 0.112 | G90: =C90/D90*1000000 -> 7335.2416 | H90: =G90/G$228 -> 0.09422922 | I90: =IFERROR(E90/G$229,"-") -> 13.132705
B91: Hong Kong | C91: 551205.67 | D91: 7410000 | E91: 0 | G91: =C91/D91*1000000 -> 74386.73 | H91: =G91/G$228 -> 0.95557909 | I91: =IFERROR(E91/G$229,"-") -> 0
B92: Hungary | C92: 436378.33 | D92: 9680000 | E92: 0.024 | G92: =C92/D92*1000000 -> 45080.406 | H92: =G92/G$228 -> 0.57910724 | I92: =IFERROR(E92/G$229,"-") -> 2.8141511
B93: Iceland | C93: 29996 | D93: 390000 | E93: 0.04 | G93: =C93/D93*1000000 -> 76912.821 | H93: =G93/G$228 -> 0.98802949 | I93: =IFERROR(E93/G$229,"-") -> 4.6902518
B94: India | C94: 16027290 | D94: 1450940000 | E94: 0.164 | G94: =C94/D94*1000000 -> 11046.143 | H94: =G94/G$228 -> 0.14189981 | I94: =IFERROR(E94/G$229,"-") -> 19.230032
B95: Indonesia | C95: 4591457 | D95: 283490000 | E95: 0.126 | G95: =C95/D95*1000000 -> 16196.187 | H95: =G95/G$228 -> 0.20805777 | I95: =IFERROR(E95/G$229,"-") -> 14.774293
...

Sheet Table Dev GDP, POP, AG
B1: TABLE DEVELOPMENT SHEET
B2: Cleaned-up and harmonised
B3: SEE BELOW THESE THREE TABLES FOR THE FINAL TABLE FOR USE IN THE 'GDP pop Data' WORKSHEET
B5: https://en.wikipedia.org/wiki/List_of_countries_by_GDP_(PPP) | J5: https://en.wikipedia.org/wiki/List_of_countries_and_dependencies_by_population | O5: https://en.wikipedia.org/wiki/List_of_countries_by_GDP_sector_composition
B6: GDP (PPP) | P6: 2017
B7: Country or territory | C7: IMF | D7: World Bank | E7: CIA | F7: GDP millions (USD) | H7: Country checker | J7: Location | K7: Population | M7: Country checker | O7: Country/Economy | P7: % GDP from Agriculture
B8: Afghanistan | C8: 72512 | D8: 91272 | E8: 82238 | F8: =AVERAGE(C8:E8) -> 82007.333 | H8: =IF(B8<>J8,"DOH!","OK") -> OK | J8: Afghanistan | K8: 43844000 | M8: =IF(J8<>O8,"DOH!","OK") -> OK | O8: Afghanistan | P8: 0.23
B9: Albania | C9: 63080 | D9: 63761 | E9: 51360 | F9: =AVERAGE(C9:E9) -> 59400.333 | H9: =IF(B9<>J9,"DOH!","OK") -> OK | J9: Albania | K9: 2363314 | M9: =IF(J9<>O9,"DOH!","OK") -> OK | O9: Albania | P9: 0.217
B10: Algeria | C10: 875334 | D10: 821721 | E10: 722912 | F10: =AVERAGE(C10:E10) -> 806655.67 | H10: =IF(B10<>J10,"DOH!","OK") -> OK | J10: Algeria | K10: 47400000 | M10: =IF(J10<>O10,"DOH!","OK") -> OK | O10: Algeria | P10: 0.133
B11: Andorra | C11: 6423 | D11: 6140 | E11: 5402 | F11: =AVERAGE(C11:E11) -> 5988.3333 | H11: =IF(B11<>J11,"DOH!","OK") -> OK | J11: Andorra | K11: 88306 | M11: =IF(J11<>O11,"DOH!","OK") -> OK | O11: Andorra | P11: 0.119
B12: Angola | C12: 402155 | D12: 316269 | E12: 278239 | F12: =AVERAGE(C12:E12) -> 332221 | H12: =IF(B12<>J12,"DOH!","OK") -> OK | J12: Angola | K12: 36170961 | M12: =IF(J12<>O12,"DOH!","OK") -> OK | O12: Angola | P12: 0.102
B13: Antigua and Barbuda | C13: 3333 | D13: 3151 | E13: 2772 | F13: =AVERAGE(C13:E13) -> 3085.3333 | H13: =IF(B13<>J13,"DOH!","OK") -> OK | J13: Antigua and Barbuda | K13: 103603 | M13: =IF(J13<>O13,"DOH!","OK") -> OK | O13: Antigua and Barbuda | P13: 0.018
B14: Argentina | C14: 1493423 | D14: 1378906 | E14: 1213000 | F14: =AVERAGE(C14:E14) -> 1361776.3 | H14: =IF(B14<>J14,"DOH!","OK") -> OK | J14: Argentina | K14: 46735004 | M14: =IF(J14<>O14,"DOH!","OK") -> OK | O14: Argentina | P14: 0.108
B15: Armenia | C15: 74294 | D15: 69234 | E15: 60909 | F15: =AVERAGE(C15:E15) -> 68145.667 | H15: =IF(B15<>J15,"DOH!","OK") -> OK | J15: Armenia | K15: 3081100 | M15: =IF(J15<>O15,"DOH!","OK") -> OK | O15: Armenia | P15: 0.167
B16: Aruba | C16: 5524 | D16: 4828 | E16: 4350 | F16: =AVERAGE(C16:E16) -> 4900.6667 | H16: =IF(B16<>J16,"DOH!","OK") -> OK | J16: Aruba | K16: 107566 | M16: =IF(J16<>O16,"DOH!","OK") -> OK | O16: Aruba | P16: 0.004
B17: Australia | C17: 1980022 | D17: 1936798 | E17: 1635000 | F17: =AVERAGE(C17:E17) -> 1850606.7 | H17: =IF(B17<>J17,"DOH!","OK") -> OK | J17: Australia | K17: 27536874 | M17: =IF(J17<>O17,"DOH!","OK") -> OK | O17: Australia | P17: 0.036
B18: Austria | C18: 682861 | D18: 657344 | E18: 581131 | F18: =AVERAGE(C18:E18) -> 640445.33 | H18: =IF(B18<>J18,"DOH!","OK") -> OK | J18: Austria | K18: 9200931 | M18: =IF(J18<>O18,"DOH!","OK") -> OK | O18: Austria | P18: 0.013
B19: Azerbaijan | C19: 272100 | D19: 255979 | E19: 225198 | F19: =AVERAGE(C19:E19) -> 251092.33 | H19: =IF(B19<>J19,"DOH!","OK") -> OK | J19: Azerbaijan | K19: 10241722 | M19: =IF(J19<>O19,"DOH!","OK") -> OK | O19: Azerbaijan | P19: 0.061
... B27: Benin | C27: 69509 | D27: 64136 | E27: 56424 | F27: =AVERAGE(C27:E27) -> 63356.333 | H27: =IF(B27<>J27,"DOH!","OK") -> OK | J27: Benin | K27: 13224860 | M27: =IF(J27<>O27,"DOH!","OK") -> OK | O27: Benin | P27: 0.261
B28: Bermuda | C28: — | D28: 7738 | E28: 6808 | F28: =AVERAGE(C28:E28) -> 7273 | H28: =IF(B28<>J28,"DOH!","OK") -> OK | J28: Bermuda | K28: 64055 | M28: =IF(J28<>O28,"DOH!","OK") -> OK | O28: Bermuda | P28: 0.009
B29: Bhutan | C29: 14106 | D29: 12782 | E29: 11517 | F29: =AVERAGE(C29:E29) -> 12801.667 | H29: =IF(B29<>J29,"DOH!","OK") -> OK | J29: Bhutan | K29: 784043 | M29: =IF(J29<>O29,"DOH!","OK") -> OK | O29: Bhutan | P29: 0.162
B30: Bolivia | C30: 144098 | D30: 138903 | E30: 122200 | F30: =AVERAGE(C30:E30) -> 135067 | H30: =IF(B30<>J30,"DOH!","OK") -> OK | J30: Bolivia | K30: 11365333 | M30: =IF(J30<>O30,"DOH!","OK") -> OK | O30: Bolivia | P30: 0.138
B31: Bosnia and Herzegovina | C31: 78655 | D31: 69522 | E31: 64641 | F31: =AVERAGE(C31:E31) -> 70939.333 | H31: =IF(B31<>J31,"DOH!","OK") -> OK | J31: Bosnia and Herzegovina | K31: 3422000 | M31: =IF(J31<>O31,"DOH!","OK") -> OK | O31: Bosnia and Herzegovina | P31: 0.068
B32: Botswana | C32: 52961 | D32: 51779 | E32: 45553 | F32: =AVERAGE(C32:E32) -> 50097.667 | H32: =IF(B32<>J32,"DOH!","OK") -> OK | J32: Botswana | K32: 2359609 | M32: =IF(J32<>O32,"DOH!","OK") -> OK | O32: Botswana | P32: 0.018
B33: Brazil | C33: 4958122 | D33: 4734651 | E33: 4165000 | F33: =AVERAGE(C33:E33) -> 4619257.7 | H33: =IF(B33<>J33,"DOH!","OK") -> OK | J33: Brazil | K33: 213421037 | M33: =IF(J33<>O33,"DOH!","OK") -> OK | O33: Brazil | P33: 0.066
B34: Brunei | C34: 43833 | D34: 41648 | E34: 36640 | F34: =AVERAGE(C34:E34) -> 40707 | H34: =IF(B34<>J34,"DOH!","OK") -> OK | J34: Brunei | K34: 455500 | M34: =IF(J34<>O34,"DOH!","OK") -> OK | O34: Brunei | P34: 0.012
B35: Bulgaria | C35: 264699 | D35: 264774 | E35: 219645 | F35: =AVERAGE(C35:E35) -> 249706 | H35: =IF(B35<>J35,"DOH!","OK") -> OK | J35: Bulgaria | K35: 6437360 | M35: =IF(J35<>O35,"DOH!","OK") -> OK | O35: Bulgaria | P35: 0.043
B36: Burkina Faso | C36: 72820 | D36: 68202 | E36: 60001 | F36: =AVERAGE(C36:E36) -> 67007.667 | H36: =IF(B36<>J36,"DOH!","OK") -> OK | J36: Burkina Faso | K36: 24070553 | M36: =IF(J36<>O36,"DOH!","OK") -> OK | O36: Burkina Faso | P36: 0.31
B37: Burundi | C37: 13975 | D37: 13343 | E37: 11739 | F37: =AVERAGE(C37:E37) -> 13019 | H37: =IF(B37<>J37,"DOH!","OK") -> OK | J37: Burundi | K37: 12332788 | M37: =IF(J37<>O37,"DOH!","OK") -> OK | O37: Burundi | P37: 0.395
B38: Cambodia | C38: 150047 | D38: 140580 | E38: 123676 | F38: =AVERAGE(C38:E38) -> 138101 | H38: =IF(B38<>J38,"DOH!","OK") -> OK | J38: Cambodia | K38: 17577760 | M38: =IF(J38<>O38,"DOH!","OK") -> OK | O38: Cambodia | P38: 0.253
B39: Cameroon | C39: 172974 | D39: 162845 | E39: 143264 | F39: =AVERAGE(C39:E39) -> 159694.33 | H39: =IF(B39<>J39,"DOH!","OK") -> OK | J39: Cameroon | K39: 29442327 | M39: =IF(J39<>O39,"DOH!","OK") -> OK | O39: Cameroon | P39: 0.167
B40: Canada | C40: 2730110 | D40: 2702880 | E40: 2341000 | F40: =AVERAGE(C40:E40) -> 2591330 | H40: =IF(B40<>J40,"DOH!","OK") -> OK | J40: Canada | K40: 41651653 | M40: =IF(J40<>O40,"DOH!","OK") -> OK | O40: Canada | P40: 0.016
B41: Cape Verde | C41: 6299 | D41: 5911 | E41: 5200 | F41: =AVERAGE(C41:E41) -> 5803.3333 | H41: =IF(B41<>J41,"DOH!","OK") -> OK | J41: Cape Verde | K41: 491233 | M41: =IF(J41<>O41,"DOH!","OK") -> OK | O41: Cape Verde | P41: 0.089
B42: Cayman Islands | C42: — | D42: 6332 | E42: 5705 | F42: =AVERAGE(C42:E42) -> 6018.5 | H42: =IF(B42<>J42,"DOH!","OK") -> OK | J42: Cayman Islands | K42: 84738 | M42: =IF(J42<>O42,"DOH!","OK") -> OK | O42: Cayman Islands | P42: 0.003
B43: Central African Republic | C43: 7332 | D43: 6736 | E43: 5926 | F43: =AVERAGE(C43:E43) -> 6664.6667 | H43: =IF(B43<>J43,"DOH!","OK") -> OK | J43: Central African Republic | K43: 6470307 | M43: =IF(J43<>O43,"DOH!","OK") -> OK | O43: Central African Republic | P43: 0.432
B44: Chad | C44: 56653 | D44: 60125 | E44: 52895 | F44: =AVERAGE(C44:E44) -> 56557.667 | H44: =IF(B44<>J44,"DOH!","OK") -> OK | J44: Chad | K44: 19340757 | M44: =IF(J44<>O44,"DOH!","OK") -> OK | O44: Chad | P44: 0.523
B45: Chile | C45: 710195 | D45: 684595 | E45: 596556 | F45: =AVERAGE(C45:E45) -> 663782 | H45: =IF(B45<>J45,"DOH!","OK") -> OK | J45: Chile | K45: 20206953 | M45: =IF(J45<>O45,"DOH!","OK") -> OK | O45: Chile | P45: 0.042
B46: China | C46: 40716448 | D46: 38190085 | E46: 33598000 | F46: =AVERAGE(C46:E46) -> 37501511 | H46: =IF(B46<>J46,"DOH!","OK") -> OK | J46: China | K46: 1408280000 | M46: =IF(J46<>O46,"DOH!","OK") -> OK | O46: China | P46: 0.079
B47: Colombia | C47: 1190795 | D47: 1136771 | E47: 978592 | F47: =AVERAGE(C47:E47) -> 1102052.7 | H47: =IF(B47<>J47,"DOH!","OK") -> OK | J47: Colombia | K47: 53057212 | M47: =IF(J47<>O47,"DOH!","OK") -> OK | O47: Colombia | P47: 0.072
B48: Comoros | C48: 3655 | D48: 3514 | E48: 3092 | F48: =AVERAGE(C48:E48) -> 3420.3333 | H48: =IF(B48<>J48,"DOH!","OK") -> OK | J48: Comoros | K48: 870038 | M48: =IF(J48<>O48,"DOH!","OK") -> OK | O48: Comoros | P48: 0.477
...

Sheet Table of Hazards (AI only)
B1: Summary Table of EIQ and PEA for ACTIVE INGREDIENTS (HAZARD)
B2: This is NOT field level risk as the concentration and application rate are not included
I4: EIQ | M4: PEA
B5: Active Ingredient | C5: EIQ Farmworker | D5: EIQ Consumer | E5: EIQ Environmental | F5: PEA Farmworker | G5: PEA Consumer | H5: PEA Environmental | I5: Farmworker | J5: Consumer | K5: Environmental | L5: Average | M5: Farmworker | N5: Consumer | O5: Environmental | P5: Sum
B6: Abamectin | C6: 90 | D6: 4 | E6: 44 | F6: 0.60749519 | G6: 4.6156268 | H6: 1.8452632 | I6: =C6 -> 90 | J6: =D6 -> 4 | K6: =E6 -> 44 | L6: =AVERAGE(C6:E6) -> 46 | M6: =F6 -> 0.60749519 | N6: =G6 -> 4.6156268 | O6: =H6 -> 1.8452632 | P6: =SUM(F6:H6) -> 7.0683852
B7: Acequinocyl | C7: 15 | D7: 3.5 | E7: 18 | F7: 0.3037476 | G7: 4.6156268 | H7: 1.1651701 | I7: =SUM(C7,D7) -> 18.5 | J7: =D7 -> 3.5 | K7: =E7 -> 18 | L7: =AVERAGE(C7:E7) -> 12.166667 | M7: =F7 -> 0.3037476 | N7: =G7 -> 4.6156268 | O7: =H7 -> 1.1651701 | P7: =SUM(F7:H7) -> 6.0845445
B8: Acetamiprid | C8: 6 | D8: 4 | E8: 42 | F8: 0.3037476 | G8: 4.6156268 | H8: 1.4304357 | I8: =SUM(C8,D8) -> 10 | J8: =D8 -> 4 | K8: =E8 -> 42 | L8: =AVERAGE(C8:E8) -> 17.333333 | M8: =F8 -> 0.3037476 | N8: =G8 -> 4.6156268 | O8: =H8 -> 1.4304357 | P8: =SUM(F8:H8) -> 6.3498101
B9: Acibenzolar-S-methyl | C9: 21 | D9: 11.5 | E9: 14 | F9: 0.3037476 | G9: 4.6156268 | H9: 1.1651701 | I9: =SUM(C9,D9) -> 32.5 | J9: =D9 -> 11.5 | K9: =E9 -> 14 | L9: =AVERAGE(C9:E9) -> 15.5 | M9: =F9 -> 0.3037476 | N9: =G9 -> 4.6156268 | O9: =H9 -> 1.1651701 | P9: =SUM(F9:H9) -> 6.0845445
B10: Acrinathrin | C10: 15 | D10: 6 | E10: 51 | F10: 0.3037476 | G10: 4.6156268 | H10: 2.0650746 | I10: =SUM(C10,D10) -> 21 | J10: =D10 -> 6 | K10: =E10 -> 51 | L10: =AVERAGE(C10:E10) -> 24 | M10: =F10 -> 0.3037476 | N10: =G10 -> 4.6156268 | O10: =H10 -> 2.0650746 | P10: =SUM(F10:H10) -> 6.984449
B11: Alpha-cypermethrin | C11: 18 | D11: 7 | E11: 41 | F11: 0.3037476 | G11: 4.6156268 | H11: 1.799809 | I11: =SUM(C11,D11) -> 25 | J11: =D11 -> 7 | K11: =E11 -> 41 | L11: =AVERAGE(C11:E11) -> 22 | M11: =F11 -> 0.3037476 | N11: =G11 -> 4.6156268 | O11: =H11 -> 1.799809 | P11: =SUM(F11:H11) -> 6.7191835
B12: Ametoctradin | C12: 12 | D12: 3 | E12: 26 | F12: 0.3037476 | G12: 4.6156268 | H12: 1.5799976 | I12: =SUM(C12,D12) -> 15 | J12: =D12 -> 3 | K12: =E12 -> 26 | L12: =AVERAGE(C12:E12) -> 13.666667 | M12: =F12 -> 0.3037476 | N12: =G12 -> 4.6156268 | O12: =H12 -> 1.5799976 | P12: =SUM(F12:H12) -> 6.4993721
B13: Amisulbrom | C13: 21 | D13: 4.5 | E13: 16 | F13: 0.3037476 | G13: 4.6156268 | H13: 1.5799976 | I13: =SUM(C13,D13) -> 25.5 | J13: =D13 -> 4.5 | K13: =E13 -> 16 | L13: =AVERAGE(C13:E13) -> 13.833333 | M13: =F13 -> 0.3037476 | N13: =G13 -> 4.6156268 | O13: =H13 -> 1.5799976 | P13: =SUM(F13:H13) -> 6.4993721
B14: Azadirachtin | C14: 6 | D14: 6 | E14: 42 | F14: 0.3037476 | G14: 5.230615 | H14: 1.5799976 | I14: =SUM(C14,D14) -> 12 | J14: =D14 -> 6 | K14: =E14 -> 42 | L14: =AVERAGE(C14:E14) -> 18 | M14: =F14 -> 0.3037476 | N14: =G14 -> 5.230615 | O14: =H14 -> 1.5799976 | P14: =SUM(F14:H14) -> 7.1143602
B15: Azoxystrobin | C15: 15 | D15: 25.5 | E15: 26 | F15: 0.3037476 | G15: 9.2312536 | H15: 1.5799976 | I15: =SUM(C15,D15) -> 40.5 | J15: =D15 -> 25.5 | K15: =E15 -> 26 | L15: =AVERAGE(C15:E15) -> 22.166667 | M15: =F15 -> 0.3037476 | N15: =G15 -> 9.2312536 | O15: =H15 -> 1.5799976 | P15: =SUM(F15:H15) -> 11.114999
B16: Bacillus thuringiensis Berliner subsp. Kurstaki | C16: 6 | D16: 2 | E16: 12 | F16: 0.3037476 | G16: 4.6156268 | H16: 1.1651701 | I16: =SUM(C16,D16) -> 8 | J16: =D16 -> 2 | K16: =E16 -> 12 | L16: =AVERAGE(C16:E16) -> 6.6666667 | M16: =F16 -> 0.3037476 | N16: =G16 -> 4.6156268 | O16: =H16 -> 1.1651701 | P16: =SUM(F16:H16) -> 6.0845445
B17: Beauveria bassiana ATCC 74040 | C17: 6 | D17: 2 | E17: 12 | F17: 0.3037476 | G17: 4.6156268 | H17: 1.1651701 | I17: =SUM(C17,D17) -> 8 | J17: =D17 -> 2 | K17: =E17 -> 12 | L17: =AVERAGE(C17:E17) -> 6.6666667 | M17: =F17 -> 0.3037476 | N17: =G17 -> 4.6156268 | O17: =H17 -> 1.1651701 | P17: =SUM(F17:H17) -> 6.0845445
B18: Benalaxyl | C18: 12 | D18: 15 | E18: 17 | F18: 0.3037476 | G18: 4.9231209 | H18: 1.1651701 | I18: =SUM(C18,D18) -> 27 | J18: =D18 -> 15 | K18: =E18 -> 17 | L18: =AVERAGE(C18:E18) -> 14.666667 | M18: =F18 -> 0.3037476 | N18: =G18 -> 4.9231209 | O18: =H18 -> 1.1651701 | P18: =SUM(F18:H18) -> 6.3920386
... B129: Zoxamide | C129: 6 | D129: 4 | E129: 14 | F129: 0.3037476 | G129: 4.6156268 | H129: 1.1651701 | I129: =SUM(C129,D129) -> 10 | J129: =D129 -> 4 | K129: =E129 -> 14 | L129: =AVERAGE(C129:E129) -> 8 | M129: =F129 -> 0.3037476 | N129: =G129 -> 4.6156268 | O129: =H129 -> 1.1651701 | P129: =SUM(F129:H129) -> 6.0845445
D149: PEA (€ per 1 kg of ai)
D150: Farmworker | E150: Consumer | F150: Environmental | G150: Sum
C151: Abamectin | D151: =VLOOKUP($C151,$B$6:$P$129,12,0) -> 0.60749519 | E151: =VLOOKUP($C151,$B$6:$P$129,13,0) -> 4.6156268 | F151: =VLOOKUP($C151,$B$6:$P$129,14,0) -> 1.8452632 | G151: =VLOOKUP($C151,$B$6:$P$129,15,0) -> 7.0683852
C152: Acetamiprid | D152: =VLOOKUP($C152,$B$6:$P$129,12,0) -> 0.3037476 | E152: =VLOOKUP($C152,$B$6:$P$129,13,0) -> 4.6156268 | F152: =VLOOKUP($C152,$B$6:$P$129,14,0) -> 1.4304357 | G152: =VLOOKUP($C152,$B$6:$P$129,15,0) -> 6.3498101
C153: Alpha-cypermethrin | D153: =VLOOKUP($C153,$B$6:$P$129,12,0) -> 0.3037476 | E153: =VLOOKUP($C153,$B$6:$P$129,13,0) -> 4.6156268 | F153: =VLOOKUP($C153,$B$6:$P$129,14,0) -> 1.799809 | G153: =VLOOKUP($C153,$B$6:$P$129,15,0) -> 6.7191835
C154: Azadirachtin | D154: =VLOOKUP($C154,$B$6:$P$129,12,0) -> 0.3037476 | E154: =VLOOKUP($C154,$B$6:$P$129,13,0) -> 5.230615 | F154: =VLOOKUP($C154,$B$6:$P$129,14,0) -> 1.5799976 | G154: =VLOOKUP($C154,$B$6:$P$129,15,0) -> 7.1143602
C155: Chlorantraniliprole | D155: =VLOOKUP($C155,$B$6:$P$129,12,0) -> 0.3037476 | E155: =VLOOKUP($C155,$B$6:$P$129,13,0) -> 5.230615 | F155: =VLOOKUP($C155,$B$6:$P$129,14,0) -> 1.5799976 | G155: =VLOOKUP($C155,$B$6:$P$129,15,0) -> 7.1143602
C156: Chlorpyrifos-methyl | D156: =VLOOKUP($C156,$B$6:$P$129,12,0) -> 0.3037476 | E156: =VLOOKUP($C156,$B$6:$P$129,13,0) -> 4.6156268 | F156: =VLOOKUP($C156,$B$6:$P$129,14,0) -> 1.3849815 | G156: =VLOOKUP($C156,$B$6:$P$129,15,0) -> 6.3043559
C157: Deltamethrin | D157: =VLOOKUP($C157,$B$6:$P$129,12,0) -> 0.3037476 | E157: =VLOOKUP($C157,$B$6:$P$129,13,0) -> 4.6156268 | F157: =VLOOKUP($C157,$B$6:$P$129,14,0) -> 2.0650746 | G157: =VLOOKUP($C157,$B$6:$P$129,15,0) -> 6.984449
C158: Etofenprox | D158: =VLOOKUP($C158,$B$6:$P$129,12,0) -> 0.3037476 | E158: =VLOOKUP($C158,$B$6:$P$129,13,0) -> 4.6156268 | F158: =VLOOKUP($C158,$B$6:$P$129,14,0) -> 2.0650746 | G158: =VLOOKUP($C158,$B$6:$P$129,15,0) -> 6.984449
C159: Imidacloprid | D159: =VLOOKUP($C159,$B$6:$P$129,12,0) -> 0.3037476 | E159: =VLOOKUP($C159,$B$6:$P$129,13,0) -> 9.5387477 | F159: =VLOOKUP($C159,$B$6:$P$129,14,0) -> 2.3303402 | G159: =VLOOKUP($C159,$B$6:$P$129,15,0) -> 12.172836
C160: Lambda-cyhalothrin | D160: =VLOOKUP($C160,$B$6:$P$129,12,0) -> 0.55953505 | E160: =VLOOKUP($C160,$B$6:$P$129,13,0) -> 4.6156268 | F160: =VLOOKUP($C160,$B$6:$P$129,14,0) -> 2.0650746 | G160: =VLOOKUP($C160,$B$6:$P$129,15,0) -> 7.2402365
C161: Malathion | D161: =VLOOKUP($C161,$B$6:$P$129,12,0) -> 0.3037476 | E161: =VLOOKUP($C161,$B$6:$P$129,13,0) -> 4.6156268 | F161: =VLOOKUP($C161,$B$6:$P$129,14,0) -> 2.0650746 | G161: =VLOOKUP($C161,$B$6:$P$129,15,0) -> 6.984449
C162: Phosmet | D162: =VLOOKUP($C162,$B$6:$P$129,12,0) -> 0.55953505 | E162: =VLOOKUP($C162,$B$6:$P$129,13,0) -> 4.6156268 | F162: =VLOOKUP($C162,$B$6:$P$129,14,0) -> 1.9155127 | G162: =VLOOKUP($C162,$B$6:$P$129,15,0) -> 7.0906745
... C165: Spirotetramat | D165: =VLOOKUP($C165,$B$6:$P$129,12,0) -> 0.3037476 | E165: =VLOOKUP($C165,$B$6:$P$129,13,0) -> 4.6156268 | F165: =VLOOKUP($C165,$B$6:$P$129,14,0) -> 1.5799976 | G165: =VLOOKUP($C165,$B$6:$P$129,15,0) -> 6.4993721
C167: THESE CELLS ARE LINKED TO TABLE ABOVE CUT AND PASTE THESE AS VALUES TO THE ECONOMIC MODEL '2.8 PEA' WORKSHEET
D168: Pyrethroids | I168: Neonicitinoids | K168: Keto-enols | M168: Organophosphates | P168: IGRs | Q168: Diamides | R168: Avermectins
D169: Deltamethrin | E169: Lambda-cyhalothrin | F169: Alpha-cypermethrin | G169: Etofenprox | H169: Pyrethrins | I169: Imidacloprid | J169: Acetamiprid | K169: Spirotetramat | L169: Spinosad | M169: Chlorpyrifos-methyl | N169: Phosmet | O169: Malathion | P169: Azadirachtin | Q169: Chlorantraniliprole | R169: Abamectin
B170: PEA (€/ha per 1 kg of ai) | C170: Farmworker | D170: =D157 -> 0.3037476 | E170: =D160 -> 0.55953505 | F170: =D153 -> 0.3037476 | G170: =D158 -> 0.3037476 | H170: =D163 -> 0.3037476 | I170: =D159 -> 0.3037476 | J170: =D152 -> 0.3037476 | K170: =D165 -> 0.3037476 | L170: =D164 -> 0.3037476 | M170: =D156 -> 0.3037476 | N170: =D162 -> 0.55953505 | O170: =D161 -> 0.3037476 | P170: =D154 -> 0.3037476 | Q170: =D155 -> 0.3037476 | R170: =D151 -> 0.60749519
C171: Consumer | D171: =E157 -> 4.6156268 | E171: =E160 -> 4.6156268 | F171: =E153 -> 4.6156268 | G171: =E158 -> 4.6156268 | H171: =E163 -> 4.6156268 | I171: =E159 -> 9.5387477 | J171: =E152 -> 4.6156268 | K171: =E165 -> 4.6156268 | L171: =E164 -> 4.9231209 | M171: =E156 -> 4.6156268 | N171: =E162 -> 4.6156268 | O171: =E161 -> 4.6156268 | P171: =E154 -> 5.230615 | Q171: =E155 -> 5.230615 | R171: =E151 -> 4.6156268
C172: Environmental | D172: =F157 -> 2.0650746 | E172: =F160 -> 2.0650746 | F172: =F153 -> 1.799809 | G172: =F158 -> 2.0650746 | H172: =F163 -> 1.799809 | I172: =F159 -> 2.3303402 | J172: =F152 -> 1.4304357 | K172: =F165 -> 1.5799976 | L172: =F164 -> 1.3849815 | M172: =F156 -> 1.3849815 | N172: =F162 -> 1.9155127 | O172: =F161 -> 2.0650746 | P172: =F154 -> 1.5799976 | Q172: =F155 -> 1.5799976 | R172: =F151 -> 1.8452632
